<?xml version="1.0" encoding="UTF-8"?>
<testng-results skipped="0" failed="1" ignored="0" total="1" passed="0">
  <reporter-output>
    <line>
      <![CDATA[Test Teststarted at13-05-2017-01-49-56]]>
    </line>
    <line>
      <![CDATA[Test testA started at13-05-2017-01-49-56]]>
    </line>
    <line>
      <![CDATA[Test testA failed at 13-05-2017-01-49-56]]>
    </line>
  </reporter-output>
  <suite name="Suite" duration-ms="165" started-at="2017-05-13T08:19:56Z" finished-at="2017-05-13T08:19:56Z">
    <groups>
    </groups>
    <test name="Test" duration-ms="165" started-at="2017-05-13T08:19:56Z" finished-at="2017-05-13T08:19:56Z">
      <class name="uk.co.bt.script.Sample">
        <test-method status="FAIL" signature="testA()[pri:0, instance:uk.co.bt.script.Sample@66a3ffec]" name="testA" duration-ms="37" started-at="2017-05-13T13:49:56Z" finished-at="2017-05-13T13:49:56Z">
          <exception class="java.lang.AssertionError">
            <message>
              <![CDATA[null]]>
            </message>
            <full-stacktrace>
              <![CDATA[java.lang.AssertionError: null
	at org.testng.Assert.fail(Assert.java:93)
	at org.testng.Assert.fail(Assert.java:100)
	at uk.co.bt.script.Sample.testA(Sample.java:11)
	at sun.reflect.NativeMethodAccessorImpl.invoke0(Native Method)
	at sun.reflect.NativeMethodAccessorImpl.invoke(Unknown Source)
	at sun.reflect.DelegatingMethodAccessorImpl.invoke(Unknown Source)
	at java.lang.reflect.Method.invoke(Unknown Source)
	at org.testng.internal.MethodInvocationHelper.invokeMethod(MethodInvocationHelper.java:108)
	at org.testng.internal.Invoker.invokeMethod(Invoker.java:661)
	at org.testng.internal.Invoker.invokeTestMethod(Invoker.java:869)
	at org.testng.internal.Invoker.invokeTestMethods(Invoker.java:1193)
	at org.testng.internal.TestMethodWorker.invokeTestMethods(TestMethodWorker.java:126)
	at org.testng.internal.TestMethodWorker.run(TestMethodWorker.java:109)
	at org.testng.TestRunner.privateRun(TestRunner.java:744)
	at org.testng.TestRunner.run(TestRunner.java:602)
	at org.testng.SuiteRunner.runTest(SuiteRunner.java:380)
	at org.testng.SuiteRunner.runSequentially(SuiteRunner.java:375)
	at org.testng.SuiteRunner.privateRun(SuiteRunner.java:340)
	at org.testng.SuiteRunner.run(SuiteRunner.java:289)
	at org.testng.SuiteRunnerWorker.runSuite(SuiteRunnerWorker.java:52)
	at org.testng.SuiteRunnerWorker.run(SuiteRunnerWorker.java:86)
	at org.testng.TestNG.runSuitesSequentially(TestNG.java:1301)
	at org.testng.TestNG.runSuitesLocally(TestNG.java:1226)
	at org.testng.TestNG.runSuites(TestNG.java:1144)
	at org.testng.TestNG.run(TestNG.java:1115)
	at org.testng.remote.AbstractRemoteTestNG.run(AbstractRemoteTestNG.java:132)
	at org.testng.remote.RemoteTestNG.initAndRun(RemoteTestNG.java:230)
	at org.testng.remote.RemoteTestNG.main(RemoteTestNG.java:76)
]]>
            </full-stacktrace>
          </exception> <!-- java.lang.AssertionError -->
          <reporter-output>
            <line>
              <![CDATA[Test testA started at13-05-2017-01-49-56]]>
            </line>
            <line>
              <![CDATA[Test testA failed at 13-05-2017-01-49-56]]>
            </line>
          </reporter-output>
        </test-method> <!-- testA -->
      </class> <!-- uk.co.bt.script.Sample -->
    </test> <!-- Test -->
  </suite> <!-- Suite -->
</testng-results>
